---
title: "CPF3204Exception class        | QSYS API Reference Guide"
description: "The exception that is thrown when Cannot find object needed for file {0} in {1}. "
last_modified_at: 2024-08-09T16:18:25Z
---

The exception that is thrown when Cannot find object needed for file {0} in {1}.

**Namespace:** ASNA.QSys.Runtime.JobSupport
**Assembly:** ASNA.QSys.Runtime.dll

**Inheritance:** [Object](https://docs.microsoft.com/en-us/dotnet/api/system.object) --> [Exception](https://docs.microsoft.com/en-us/dotnet/api/system.exception) --> [JobException](/reference/runtime/qsys-runtime-job-support/job-exception.html) --> [CPF0000Exception](/reference/runtime/qsys-runtime-job-support/cpf-exceptions/cpf0000-exception.html) --> [CPF3200Exception](/reference/runtime/qsys-runtime-job-support/cpf-exceptions/cpf3200-exception.html)
<br>
<br>

## Constructors

| Name | Description |
| --- | --- |
| [CPF3204Exception](#cpf3204exceptionstring-string-exception)([String](https://docs.microsoft.com/en-us/dotnet/api/system.string), [String](https://docs.microsoft.com/en-us/dotnet/api/system.string), [Exception](https://docs.microsoft.com/en-us/dotnet/api/system.exception)) | Initializes a new instance of the CPF3204Exception class.

### CPF3204Exception([String](https://docs.microsoft.com/en-us/dotnet/api/system.string), [String](https://docs.microsoft.com/en-us/dotnet/api/system.string), [Exception](https://docs.microsoft.com/en-us/dotnet/api/system.exception))

Initializes a new instance of the CPF3204Exception class.

```cs
CPF3204Exception(String, String, Exception)
```

#### Parameters

| Type | Parameter name | Description
| --- | --- | ---
| [String](https://docs.microsoft.com/en-us/dotnet/api/system.string) | file | The name of the file.
| [String](https://docs.microsoft.com/en-us/dotnet/api/system.string) | folder | The name of the folder (or library).
| [Exception](https://docs.microsoft.com/en-us/dotnet/api/system.exception) | innerException | The exception that is the cause of the current exception, or a null reference if no inner exception is specified.
