---
title: CPF2817Exception Class
---

The exception that is thrown when Copy command ended because of error.

**Namespace:** ASNA.QSys.Runtime.JobSupport <br/>
**Assembly:** ASNA.QSys.Runtime

<br>
<br>

## Remarks

The exception that is thrown when Copy command ended because of error.

[//]: # ($$TODO: Complete the Remarks section.)

<br>
<br>

## Constructor

| Name |  Description 
| --- | --- 
| **CPF2817Exception**( [Exception](https://docs.microsoft.com/en-us/dotnet/api/system.exception) ) | Initializes a new instance of the CPF2817Exception class.

<br>

### CPF2817Exception( [Exception](https://docs.microsoft.com/en-us/dotnet/api/system.exception) )

Initializes a new instance of the CPF2817Exception class.

```cs
CPF2817Exception( Exception innerException );
```

#### Parameters

| Type | Parameter name | Description
| --- | --- | ---
| [Exception](https://docs.microsoft.com/en-us/dotnet/api/system.exception) | innerException | The exception that is the cause of the current exception, or a null reference if no inner exception is specified. 

<br>


<br>
<br>

